{
 "metadata": {
  "language_info": {
   "codemirror_mode": {
    "name": "ipython",
    "version": 3
   },
   "file_extension": ".py",
   "mimetype": "text/x-python",
   "name": "python",
   "nbconvert_exporter": "python",
   "pygments_lexer": "ipython3",
   "version": "3.7.6-final"
  },
  "orig_nbformat": 2,
  "kernelspec": {
   "name": "python3",
   "display_name": "Python 3",
   "language": "python"
  }
 },
 "nbformat": 4,
 "nbformat_minor": 2,
 "cells": [
  {
   "cell_type": "code",
   "execution_count": 2,
   "metadata": {},
   "outputs": [],
   "source": [
    "# 1) Business Question, # 2) Data Collection, # 3) Preprocessing, # 4) Model(s) Creation, # 5) Model Evaluation and Comparison , # 6) Conclusion and Future Improvements\n",
    "#https://www.kaggle.com/c/home-credit-default-risk/data?select=installments_payments.csv"
   ]
  },
  {
   "cell_type": "code",
   "execution_count": 5,
   "metadata": {},
   "outputs": [
    {
     "output_type": "error",
     "ename": "ImportError",
     "evalue": "Unable to import required dependencies:\nnumpy: \n\nIMPORTANT: PLEASE READ THIS FOR ADVICE ON HOW TO SOLVE THIS ISSUE!\n\nImporting the numpy c-extensions failed.\n- Try uninstalling and reinstalling numpy.\n- If you have already done that, then:\n  1. Check that you expected to use Python3.7 from \"C:\\ProgramData\\Anaconda3\\python.exe\",\n     and that you have no directories in your PATH or PYTHONPATH that can\n     interfere with the Python and numpy version \"1.18.1\" you're trying to use.\n  2. If (1) looks fine, you can open a new issue at\n     https://github.com/numpy/numpy/issues.  Please include details on:\n     - how you installed Python\n     - how you installed numpy\n     - your operating system\n     - whether or not you have multiple versions of Python installed\n     - if you built from source, your compiler versions and ideally a build log\n\n- If you're working with a numpy git repository, try `git clean -xdf`\n  (removes all files not under version control) and rebuild numpy.\n\nNote: this error has many possible causes, so please don't comment on\nan existing issue about this - open a new one instead.\n\nOriginal error was: DLL load failed: The specified module could not be found.\n",
     "traceback": [
      "\u001b[1;31m---------------------------------------------------------------------------\u001b[0m",
      "\u001b[1;31mImportError\u001b[0m                               Traceback (most recent call last)",
      "\u001b[1;32m<ipython-input-5-033080141ec9>\u001b[0m in \u001b[0;36m<module>\u001b[1;34m\u001b[0m\n\u001b[0;32m      1\u001b[0m \u001b[1;31m#Dataframe\u001b[0m\u001b[1;33m\u001b[0m\u001b[1;33m\u001b[0m\u001b[1;33m\u001b[0m\u001b[0m\n\u001b[1;32m----> 2\u001b[1;33m \u001b[1;32mimport\u001b[0m \u001b[0mpandas\u001b[0m \u001b[1;32mas\u001b[0m \u001b[0mpd\u001b[0m\u001b[1;33m\u001b[0m\u001b[1;33m\u001b[0m\u001b[0m\n\u001b[0m\u001b[0;32m      3\u001b[0m \u001b[1;32mimport\u001b[0m \u001b[0mnumpy\u001b[0m \u001b[1;32mas\u001b[0m \u001b[0mnp\u001b[0m\u001b[1;33m\u001b[0m\u001b[1;33m\u001b[0m\u001b[0m\n\u001b[0;32m      4\u001b[0m \u001b[1;32mimport\u001b[0m \u001b[0mmath\u001b[0m\u001b[1;33m\u001b[0m\u001b[1;33m\u001b[0m\u001b[0m\n\u001b[0;32m      5\u001b[0m \u001b[1;32mfrom\u001b[0m \u001b[0mdatetime\u001b[0m \u001b[1;32mimport\u001b[0m \u001b[0mdatetime\u001b[0m\u001b[1;33m\u001b[0m\u001b[1;33m\u001b[0m\u001b[0m\n",
      "\u001b[1;32mC:\\ProgramData\\Anaconda3\\lib\\site-packages\\pandas\\__init__.py\u001b[0m in \u001b[0;36m<module>\u001b[1;34m\u001b[0m\n\u001b[0;32m     15\u001b[0m \u001b[1;32mif\u001b[0m \u001b[0mmissing_dependencies\u001b[0m\u001b[1;33m:\u001b[0m\u001b[1;33m\u001b[0m\u001b[1;33m\u001b[0m\u001b[0m\n\u001b[0;32m     16\u001b[0m     raise ImportError(\n\u001b[1;32m---> 17\u001b[1;33m         \u001b[1;34m\"Unable to import required dependencies:\\n\"\u001b[0m \u001b[1;33m+\u001b[0m \u001b[1;34m\"\\n\"\u001b[0m\u001b[1;33m.\u001b[0m\u001b[0mjoin\u001b[0m\u001b[1;33m(\u001b[0m\u001b[0mmissing_dependencies\u001b[0m\u001b[1;33m)\u001b[0m\u001b[1;33m\u001b[0m\u001b[1;33m\u001b[0m\u001b[0m\n\u001b[0m\u001b[0;32m     18\u001b[0m     )\n\u001b[0;32m     19\u001b[0m \u001b[1;32mdel\u001b[0m \u001b[0mhard_dependencies\u001b[0m\u001b[1;33m,\u001b[0m \u001b[0mdependency\u001b[0m\u001b[1;33m,\u001b[0m \u001b[0mmissing_dependencies\u001b[0m\u001b[1;33m\u001b[0m\u001b[1;33m\u001b[0m\u001b[0m\n",
      "\u001b[1;31mImportError\u001b[0m: Unable to import required dependencies:\nnumpy: \n\nIMPORTANT: PLEASE READ THIS FOR ADVICE ON HOW TO SOLVE THIS ISSUE!\n\nImporting the numpy c-extensions failed.\n- Try uninstalling and reinstalling numpy.\n- If you have already done that, then:\n  1. Check that you expected to use Python3.7 from \"C:\\ProgramData\\Anaconda3\\python.exe\",\n     and that you have no directories in your PATH or PYTHONPATH that can\n     interfere with the Python and numpy version \"1.18.1\" you're trying to use.\n  2. If (1) looks fine, you can open a new issue at\n     https://github.com/numpy/numpy/issues.  Please include details on:\n     - how you installed Python\n     - how you installed numpy\n     - your operating system\n     - whether or not you have multiple versions of Python installed\n     - if you built from source, your compiler versions and ideally a build log\n\n- If you're working with a numpy git repository, try `git clean -xdf`\n  (removes all files not under version control) and rebuild numpy.\n\nNote: this error has many possible causes, so please don't comment on\nan existing issue about this - open a new one instead.\n\nOriginal error was: DLL load failed: The specified module could not be found.\n"
     ]
    }
   ],
   "source": [
    "#Dataframe\n",
    "import pandas as pd\n",
    "import numpy as np\n",
    "import math\n",
    "from datetime import datetime\n",
    "import scipy\n",
    "from scipy import stats\n",
    "\n",
    "# To Plot Pretty Figures:\n",
    "import seaborn as sns\n",
    "import matplotlib as mpl\n",
    "import matplotlib.pyplot as plt\n",
    "mpl.rc('axes', labelsize=14)\n",
    "mpl.rc('xtick', labelsize=12)\n",
    "mpl.rc('ytick', labelsize=12)\n",
    "\n",
    "plt.rcParams['figure.figsize'] = (13, 8)    # set default figure size...must set after matplotlib inline on a DIFFERENT cell\n",
    "plt.style.use('seaborn-deep')       # change color palette\n",
    "\n",
    "#sklearn & models\n",
    "from sklearn.model_selection import train_test_split\n",
    "from sklearn import linear_model\n",
    "from sklearn.metrics import mean_squared_error, r2_score, mean_absolute_error\n",
    "from sklearn.neighbors import KNeighborsClassifier\n",
    "from sklearn.linear_model import LogisticRegression\n",
    "from sklearn.ensemble import RandomForestClassifier\n",
    "from sklearn.ensemble import AdaBoostClassifier\n",
    "from sklearn.tree import DecisionTreeClassifier\n",
    "from xgboost import XGBClassifier\n",
    "from sklearn.metrics import confusion_matrix, classification_report, accuracy_score\n",
    "import time\n",
    "\n",
    "#Data processing\n",
    "from sklearn.preprocessing import StandardScaler\n",
    "from sklearn.preprocessing import MinMaxScaler\n",
    "from  sklearn.impute import SimpleImputer   \n",
    "from imblearn.over_sampling import SMOTE\n",
    "\n",
    "#   Print 30 lines\n",
    "pd.set_option('display.max_rows', 30)\n",
    "#   allowing for any single variable to print out without using the print statement:\n",
    "from IPython.core.interactiveshell import InteractiveShell\n",
    "InteractiveShell.ast_node_interactivity = \"all\"\n",
    "# to make this notebook's output stable across runs\n",
    "np.random.seed(42)\n"
   ]
  },
  {
   "cell_type": "code",
   "execution_count": null,
   "metadata": {},
   "outputs": [],
   "source": []
  }
 ]
}